Workbook

Sheet 数据收集总表
A1: 收集日期 | B1: 央行购金(吨) | C1: M2同比增速(%) | D1: 美债/GDP比率(%) | E1: Fed预期差(bp) | F1: 10Y TIPS(%) | G1: DXY | H1: ETF持仓4周变化(%) | I1: 金银比 | J1: 金价/AISC | K1: RSI14 | L1: MACD背离 | M1: 20日均线斜率(%) | N1: 布林带状态 | O1: VIX | P1: 信用利差(%) | Q1: GPR指数 | R1: 布油价格($) | S1: CPI同比(%) | T1: 金价($) | U1: 金价单日跌幅 | V1: DXY单日涨幅
A2: 日期 | B2: S_macro | C2: S_macro | D2: S_macro | E2: S_macro | F2: S_macro | G2: S_macro | H2: K_verif | I2: K_verif | J2: K_verif | K2: K_trend | L2: K_trend | M2: K_trend | N2: K_trend | O2: K_liquidity | P2: K_liquidity | Q2: K_geo | R2: K_geo | S2: K_geo | T2: 参考 | U2: 参考 | V2: S_macro
A3: 2026-04-30 | B3: 838 | C3: 4.2 | D3: 122.57 | E3: -15 | F3: 1.92 | G3: 98.66 | H3: -3.18 | I3: 63.75 | J3: 3.25 | K3: 39.01 | L3: 50 | M3: -0.15 | N3: 83 | O3: 17.83 | P3: 1.69 | Q3: 297.27 | R3: 111.85 | S3: 3.32 | T3: 4543.41 | U3: -1.62 | V3: 0.03
A4: 2026-05-13 | B4: 838 | C4: 4.88 | D4: 122.56815 | E4: 2.5 | F4: 1.95 | G4: 97.7146 | H4: -0.01 | I4: 53.6281 | J4: 3.3786 | K4: 37.25 | L4: 50 | M4: -0.0389 | N4: 67 | O4: 18.38 | P4: 1.65 | Q4: 122.17332 | R4: 118.26 | S4: 3.95 | T4: 4730 | U4: -0.0978 | V4: 0
A5: 2026-06-09 | B5: 870.5 | C5: 4.88 | D5: 121.03915 | E5: 2.5 | F5: 2.19 | G5: 99.8814 | H5: -1.53 | I5: 63.469857 | J5: 2.5421719 | K5: 60.62 | L5: 50 | M5: -0.27 | N5: 50 | O5: 24.76 | P5: 1.54 | Q5: 184.18 | R5: 93.031 | S5: 3.8 | T5: 4337.53 | U5: -0.01 | V5: -0.13
A6: 2026-06-16 | B6: 870.5 | C6: 4.88 | D6: 121.03915 | E6: 2.5 | F6: 2.17 | G6: 99.5807 | H6: -2.06 | I6: 61.566936 | J6: 2.5471419 | K6: 57.21 | L6: 50 | M6: 0.356 | N6: 50 | O6: 22.56 | P6: 1.63 | Q6: 184.18 | R6: 81.437 | S6: 4.2 | T6: 4346.01 | U6: -0.01 | V6: -0.09
A7: 2026-06-16 | B7: 870.5 | C7: 4.88 | D7: 121.03915 | E7: 2.5 | F7: 2.17 | G7: 99.5815 | H7: -2.06 | I7: 61.579425 | J7: 2.5469368 | K7: 57.21 | L7: 50 | M7: 0.356 | N7: 50 | O7: 22.56 | P7: 1.63 | Q7: 184.18 | R7: 81.423 | S7: 4.2 | T7: 4345.66 | U7: -0.01 | V7: -0.09
A8: 2026-06-16 | B8: 870.5 | C8: 4.88 | D8: 121.03915 | E8: 2.5 | F8: 2.17 | G8: 99.6054 | H8: -2.06 | I8: 61.608171 | J8: 2.5452372 | K8: 57.21 | L8: 50 | M8: 0.356 | N8: 50 | O8: 22.56 | P8: 1.63 | Q8: 184.18 | R8: 81.342 | S8: 4.2 | T8: 4342.76 | U8: -0.01 | V8: -0.07
A9: 2026-06-23 | B9: 870.5 | C9: 4.88 | D9: 122.77209 | E9: 2.5 | F9: 2.21 | G9: 101.065 | H9: -1.55 | I9: 65.93631 | J9: 2.4148913 | K9: 55.94 | L9: 50 | M9: 0.182 | N9: 50 | O9: 22.52 | P9: 1.59 | Q9: 184.18 | R9: 76.659 | S9: 4.2 | T9: 4120.36 | U9: -0.01 | V9: 0.06
A10: 2026-06-24 | B10: 870.5 | C10: 4.88 | D10: 122.77209 | E10: 2.5 | F10: 2.28 | G10: 101.602 | H10: -2.15 | I10: 66.579412 | J10: 2.3881071 | K10: 50.97 | L10: 50 | M10: 0.2 | N10: 50 | O10: 23.87 | P10: 1.6 | Q10: 184.18 | R10: 75.508 | S10: 4.2 | T10: 4074.66 | U10: -0.01 | V10: 0.22
A11: 2026-06-24 | B11: 870.5 | C11: 4.88 | D11: 122.77209 | E11: 2.5 | F11: 2.28 | G11: 101.6082 | H11: -2.15 | I11: 66.633628 | J11: 2.3877086 | K11: 50.97 | L11: 50 | M11: 0.2 | N11: 50 | O11: 23.87 | P11: 1.6 | Q11: 184.18 | R11: 75.337 | S11: 4.2 | T11: 4073.98 | U11: -0.01 | V11: 0.23
A12: 2026-06-25 | B12: 870.5 | C12: 4.88 | D12: 122.77209 | E12: 2.5 | F12: 2.29 | G12: 101.485 | H12: -2.32 | I12: 69.827918 | J12: 2.3425623 | K12: 55.66 | L12: 50 | M12: 0.332 | N12: 50 | O12: 23.69 | P12: 1.69 | Q12: 184.18 | R12: 72.825 | S12: 4.2 | T12: 3996.95 | U12: -0.01 | V12: -0.09
A13: 2026-06-25 | B13: 870.5 | C13: 4.88 | D13: 122.77209 | E13: 2.5 | F13: 2.29 | G13: 101.4852 | H13: -2.32 | I13: 69.642608 | J13: 2.3412436 | K13: 55.66 | L13: 50 | M13: 0.332 | N13: 50 | O13: 23.69 | P13: 1.69 | Q13: 184.18 | R13: 72.85 | S13: 4.2 | T13: 3994.7 | U13: -0.01 | V13: -0.09
A14: 2026-06-25 04:13:02 | B14: 870.5 | C14: 4.88 | D14: 122.77209 | E14: 2.5 | F14: 2.29 | G14: 101.4776 | H14: -2.32 | I14: 69.579324 | J14: 2.3391161 | K14: 55.66 | L14: 50 | M14: 0.332 | N14: 50 | O14: 23.69 | P14: 1.69 | Q14: 184.18 | R14: 72.859 | S14: 4.2 | T14: 3991.07 | U14: -0.01 | V14: -0.1
... A24: 2026-07-03 12:40:37 | B24: 870.5 | C24: 4.88 | D24: 122.59387 | E24: 2.5 | F24: 2.25 | G24: 100.7764 | H24: -3.24 | I24: 66.96633 | J24: 2.4479056 | K24: 39.25 | L24: 50 | M24: 0.54 | N24: 50 | O24: 22.040001 | P24: 1.51 | Q24: 173.64 | R24: 72.288 | S24: 4.2 | T24: 4176.69 | U24: -0.01 | V24: -0.09
A25: 数据说明：
A26: MACD背离: 100=底背离, 50=无背离, 0=顶背离
A27: 布林带状态: 100=触下轨扩口, 50=中性, 0=触上轨扩口
A28: Fed预期差: 正数=预期降息bp, 负数=预期加息bp
A29: 2026-07-04 12:33:56 | B29: 870.5 | C29: 4.88 | D29: 122.59387 | E29: 2.5 | F29: 2.25 | G29: 100.8657 | H29: -3.24 | I29: 66.94628 | J29: 2.4467803 | K29: 39.25 | L29: 50 | M29: 0.54 | N29: 50 | O29: 22.040001 | Q29: 173.64 | R29: 71.995 | S29: 4.2 | T29: 4174.77 | U29: -0.01 | V29: 0
A30: 2026-07-05 12:55:29 | B30: 870.5 | C30: 4.88 | D30: 122.59387 | E30: 2.5 | F30: 2.25 | G30: 100.8657 | H30: -3.24 | I30: 66.94628 | J30: 2.4467803 | K30: 39.25 | L30: 50 | M30: 0.54 | N30: 50 | O30: 22.24 | Q30: 173.64 | R30: 71.995 | S30: 4.2 | T30: 4174.77 | U30: -0.01 | V30: 0
A31: 2026-07-06 12:55:53 | B31: 870.5 | C31: 4.88 | D31: 122.59387 | E31: 2.5 | F31: 2.25 | G31: 100.9489 | H31: -3.24 | I31: 67.309485 | J31: 2.4371744 | K31: 39.25 | L31: 50 | M31: 0.54 | N31: 50 | O31: 22.24 | Q31: 173.64 | R31: 71.811 | S31: 4.2 | T31: 4158.38 | U31: -0.01 | V31: 0.08
A32: 2026-07-06 13:09:11 | B32: 870.5 | C32: 4.88 | D32: 122.59387 | E32: 2.5 | F32: 2.25 | G32: 100.9831 | H32: -3.24 | I32: 67.285113 | J32: 2.4343201 | K32: 39.25 | L32: 50 | M32: 0.54 | N32: 50 | O32: 22.24 | Q32: 173.64 | R32: 72 | S32: 4.2 | T32: 4153.51 | U32: -0.01 | V32: 0.12
A33: 2026-07-07 12:51:21 | B33: 870.5 | C33: 4.88 | D33: 122.59387 | E33: 2.5 | F33: 2.26 | G33: 100.8592 | H33: -2.88 | I33: 67.748154 | J33: 2.4201016 | K33: 44.4 | L33: 50 | M33: 0.402 | N33: 50 | O33: 21.49 | P33: 1.52 | Q33: 173.64 | R33: 72.522 | S33: 4.2 | T33: 4129.25 | U33: -0.01 | V33: -0.01
A34: 2026-07-08 12:13:21 | B34: 870.5 | C34: 4.88 | D34: 122.59387 | E34: 2.5 | F34: 2.24 | G34: 101.1102 | H34: -2.59 | I34: 68.376202 | J34: 2.4180913 | K34: 46.2 | L34: 50 | M34: 0.368 | N34: 50 | O34: 21.69 | P34: 1.45 | Q34: 173.64 | R34: 76.143 | S34: 4.2 | T34: 4125.82 | U34: -0.01 | V34: 0.02
A35: 2026-07-09 12:51:15 | B35: 870.5 | C35: 4.88 | D35: 122.59387 | E35: 2.5 | F35: 2.3 | G35: 100.9757 | H35: -2.59 | I35: 70.11184 | J35: 2.3808514 | K35: 49.37 | L35: 50 | M35: 0.166 | N35: 50 | O35: 22.01 | P35: 1.44 | Q35: 173.64 | R35: 78.897 | S35: 4.2 | T35: 4062.28 | U35: -0.01 | V35: -0.09
A36: 2026-07-10 12:50:40 | B36: 870.5 | C36: 4.88 | D36: 122.59387 | E36: 2.5 | F36: 2.31 | G36: 100.7793 | H36: -2.26 | I36: 68.197118 | J36: 2.4129572 | K36: 55.87 | L36: 50 | M36: 0.124 | N36: 50 | O36: 21.58 | P36: 1.46 | Q36: 173.64 | R36: 76.565 | S36: 4.2 | T36: 4117.06 | U36: -0.01 | V36: -0.15
A37: 2026-07-11 12:11:44 | B37: 870.5 | C37: 4.88 | D37: 122.59387 | E37: 2.5 | F37: 2.31 | G37: 100.9609 | H37: -2.49 | I37: 68.833723 | J37: 2.4141001 | K37: 42.04 | L37: 50 | M37: -0.072 | N37: 50 | O37: 21.13 | P37: 1.44 | Q37: 173.64 | R37: 75.229 | S37: 4.2 | T37: 4119.01 | U37: -0.02 | V37: 0.03
A38: 2026-07-12 12:24:23 | B38: 870.5 | C38: 4.88 | D38: 122.59387 | E38: 2.5 | F38: 2.31 | G38: 100.9609 | H38: -2.49 | I38: 68.833723 | J38: 2.4141001 | K38: 42.04 | L38: 50 | M38: -0.072 | N38: 50 | O38: 21.13 | P38: 1.44 | Q38: 173.64 | R38: 75.229 | S38: 4.2 | T38: 4119.01 | U38: -0.02 | V38: 0.03
A39: 2026-07-13 12:29:28 | B39: 870.5 | C39: 4.88 | D39: 122.59387 | E39: 2.5 | F39: 2.31 | G39: 101.108 | H39: -2.49 | I39: 69.795799 | J39: 2.3758462 | K39: 42.04 | L39: 50 | M39: -0.072 | N39: 50 | O39: 21.13 | P39: 1.44 | Q39: 173.64 | R39: 79.163 | S39: 4.2 | T39: 4053.74 | U39: -0.01 | V39: 0.15
A40: 2026-07-14 11:55:32 | B40: 870.5 | C40: 4.88 | D40: 122.59387 | E40: 2.5 | F40: 2.32 | G40: 101.172 | H40: -2.49 | I40: 69.673084 | J40: 2.3545184 | K40: 40.33 | L40: 50 | M40: -0.424 | N40: 50 | O40: 21.78 | P40: 1.38 | Q40: 173.64 | R40: 84.544 | S40: 4.2 | T40: 4017.35 | U40: -0.01 | V40: -0.13
A41: 2026-07-15 11:56:57 | B41: 870.5 | C41: 4.88 | D41: 122.59387 | E41: 2.5 | F41: 2.36 | G41: 100.7977 | H41: -2.18 | I41: 69.0375 | J41: 2.3629815 | K41: 51.8 | L41: 50 | M41: -0.526 | N41: 50 | O41: 21.51 | P41: 1.42 | Q41: 173.64 | R41: 85.783 | S41: 3.5 | T41: 4031.79 | U41: -0.01 | V41: -0.13
A42: 2026-07-16 12:07:34 | B42: 870.5 | C42: 4.88 | D42: 122.59387 | E42: 2.5 | F42: 2.33 | G42: 100.5147 | H42: -2.27 | I42: 70.597409 | J42: 2.3638255 | K42: 44.64 | L42: 50 | M42: -0.498 | N42: 50 | O42: 20.85 | P42: 1.45 | Q42: 173.64 | R42: 84.756 | S42: 3.5 | T42: 4033.23 | U42: -0.01 | V42: 0
A43: 2026-07-17 11:58:34 | B43: 870.5 | C43: 4.88 | D43: 122.59387 | E43: 2.5 | F43: 2.32 | G43: 100.7602 | H43: -2.27 | I43: 72.058855 | J43: 2.3392743 | K43: 31.6 | L43: 50 | M43: -0.57 | N43: 50 | O43: 21.45 | P43: 1.43 | Q43: 173.64 | R43: 85.013 | S43: 3.5 | T43: 3991.34 | U43: -0.01 | V43: 0.04
A44: 2026-07-18 11:53:37 | B44: 870.5 | C44: 4.88 | D44: 122.59387 | E44: 2.5 | F44: 2.35 | G44: 100.7617 | H44: -2.05 | I44: 71.861872 | J44: 2.3539382 | K44: 41.87 | L44: 50 | M44: -0.422 | N44: 50 | O44: 22.48 | P44: 1.45 | Q44: 173.64 | R44: 88.273 | S44: 3.5 | T44: 4016.36 | U44: -0.02 | V44: 0.04
... A55: 2026-07-29 12:10:31 | B55: 870.5 | C55: 4.88 | D55: 122.59387 | E55: 2.5 | F55: 2.44 | G55: 101.3056 | H55: -1.15 | I55: 70.13653 | J55: 2.2527878 | K55: 43.79 | L55: 50 | M55: -0.764 | N55: 50 | O55: 22.030001 | P55: 1.39 | Q55: 173.64 | R55: 85.207 | S55: 3.5 | T55: 4022.33 | U55: -0.01 | V55: -0.11
A56: 2026-07-30 11:55:28 | B56: 870.5 | C56: 4.88 | D56: 122.59387 | E56: 2.5 | F56: 2.41 | G56: 100.9416 | H56: -1.26 | J56: 2.2726142 | K56: 40.61 | L56: 50 | M56: -0.8 | N56: 50 | O56: 23.42 | P56: 1.33 | Q56: 173.64 | R56: 87.252 | S56: 3.5 | T56: 4057.73 | U56: -0.01 | V56: 0.12
A57: 2026-08-03 12:28:18 | B57: 870.5 | C57: 4.88 | D57: 120.29305 | E57: 2.5 | F57: 2.41 | G57: 99.7206 | H57: -0.63 | I57: 69.707334 | J57: 2.2784334 | K57: 52.14 | L57: 50 | M57: -0.636 | N57: 50 | O57: 21.25 | P57: 1.25 | Q57: 173.64 | R57: 83.494 | S57: 3.5 | T57: 4068.12 | U57: -0.01 | V57: -0.06
A58: 2026-08-04 12:12:13 | B58: 870.5 | C58: 4.88 | D58: 120.29305 | E58: 2.5 | F58: 2.47 | G58: 100.0225 | H58: -0.12 | I58: 69.058252 | J58: 2.2707548 | K58: 32.89 | L58: 50 | M58: -0.544 | N58: 50 | O58: 21.08 | P58: 1.49 | Q58: 152.67 | R58: 85.014 | S58: 3.5 | T58: 4054.41 | U58: -0.01 | V58: 0.06
A59: 2026-08-05 11:59:11 | B59: 870.5 | C59: 4.88 | D59: 120.29305 | E59: 2.5 | F59: 2.43 | G59: 99.8009 | H59: 0.42 | I59: 67.976128 | J59: 2.3124576 | K59: 42.4 | L59: 50 | M59: -0.494 | N59: 50 | O59: 21.27 | P59: 1.56 | Q59: 152.67 | R59: 78.332 | S59: 3.5 | T59: 4128.87 | U59: -0.01 | V59: -0.06
...

Sheet 宏观信号计算表
A1: 引用数据收集表最新一行 (最后一行有数据的行)
A2: 当前引用行: =MAX(IF(数据收集总表!A3:A22<>"",ROW(数据收集总表!A3:A22)))
A4: 因子 | B4: 权重 | C4: 当前值 | D4: 编码(+1/0/-1) | E4: 得分贡献 | F4: 阈值说明
A5: 央行购金(吨) | B5: 30% | C5: =LOOKUP(2,1/(数据收集总表!B3:B31<>""),数据收集总表!B3:B31) | D5: =IF(C5>900,1,IF(C5>=600,0,-1)) | E5: =D5*VALUE(SUBSTITUTE(B5,"%",""))/100 | F5: >900=+1, 600-900=0, <600=-1
A6: M2同比增速(%) | B6: 25% | C6: =LOOKUP(2,1/(数据收集总表!C3:C31<>""),数据收集总表!C3:C31) | D6: =IF(C6>6,1,IF(C6>=0,0,-1)) | E6: =D6*VALUE(SUBSTITUTE(B6,"%",""))/100 | F6: >6%=+1, 0%-6%=0, <0%=-1
A7: 美债/GDP比率(%) | B7: 15% | C7: =LOOKUP(2,1/(数据收集总表!D3:D31<>""),数据收集总表!D3:D31) | D7: =IF(C7>120,1,IF(C7>=100,0,-1)) | E7: =D7*VALUE(SUBSTITUTE(B7,"%",""))/100 | F7: >120%=+1, 100%-120%=0, <100%=-1
A8: Fed预期差(bp) | B8: 15% | C8: =LOOKUP(2,1/(数据收集总表!E3:E31<>""),数据收集总表!E3:E31) | D8: =IF(C8>50,1,IF(C8<-50,-1,0)) | E8: =D8*VALUE(SUBSTITUTE(B8,"%",""))/100 | F8: 降息>50bp=+1, 中间=0, 加息=-1
A9: 10Y TIPS(%) | B9: 10% | C9: =LOOKUP(2,1/(数据收集总表!F3:F31<>""),数据收集总表!F3:F31) | D9: =IF(C9<-0.5,1,IF(C9<=1.5,0,-1)) | E9: =D9*VALUE(SUBSTITUTE(B9,"%",""))/100 | F9: <-0.5%=+1, -0.5%~1.5%=0, >1.5%=-1
A10: DXY | B10: 5% | C10: =LOOKUP(2,1/(数据收集总表!G3:G31<>""),数据收集总表!G3:G31) | D10: =IF(C10<95,1,IF(C10<=105,0,-1)) | E10: =D10*VALUE(SUBSTITUTE(B10,"%",""))/100 | F10: <95=+1, 95-105=0, >105=-1
A11: S_macro 合计 | B11: 100% | E11: =SUM(E5:E10)

Sheet 验证层计算表
A1: 因子 | B1: 权重 | C1: 当前值 | D1: 得分(0-100) | E1: 加权得分 | F1: 得分规则
A2: ETF持仓4周变化(%) | B2: 40% | C2: =LOOKUP(2,1/(数据收集总表!H3:H31<>""),数据收集总表!H3:H31) | D2: =IF(C2>=2,100,IF(C2<=-2,0,(C2+2)*25)) | E2: =D2*VALUE(SUBSTITUTE(B2,"%",""))/100 | F2: ≥+2%=100, ≤-2%=0, 线性插值
A3: 金银比 | B3: 35% | C3: =LOOKUP(2,1/(数据收集总表!I3:I31<>""),数据收集总表!I3:I31) | D3: =IF(C3<=60,100,IF(C3>=100,0,(100-C3)*2.5)) | E3: =D3*VALUE(SUBSTITUTE(B3,"%",""))/100 | F3: ≤60=100, ≥100=0, 线性插值
A4: 金价/AISC | B4: 25% | C4: =LOOKUP(2,1/(数据收集总表!J3:J31<>""),数据收集总表!J3:J31) | D4: =IF(C4<=1.5,100,IF(C4>=2.5,0,(2.5-C4)*100)) | E4: =D4*VALUE(SUBSTITUTE(B4,"%",""))/100 | F4: ≤1.5=100, ≥2.5=0, 线性插值
A5: 验证层总分 V | D5: =SUM(E2:E4)
A6: K_verif | D6: =D5/100+0.5

Sheet 趋势层计算表
A1: 因子 | B1: 权重 | C1: 当前值 | D1: 得分(0-100) | E1: 加权得分 | F1: 得分规则
A2: RSI14 | B2: 30% | C2: =LOOKUP(2,1/(数据收集总表!K3:K31<>""),数据收集总表!K3:K31) | D2: =IF(C2<=30,100,IF(C2>=70,0,(70-C2)*2.5)) | E2: =D2*VALUE(SUBSTITUTE(B2,"%",""))/100 | F2: ≤30=100, 30-70递减, ≥70=0
A3: MACD背离 | B3: 25% | C3: =LOOKUP(2,1/(数据收集总表!L3:L31<>""),数据收集总表!L3:L31) | D3: =C3 | E3: =D3*VALUE(SUBSTITUTE(B3,"%",""))/100 | F3: 底背离=100, 无=50, 顶背离=0
A4: 20日均线斜率(%) | B4: 25% | C4: =LOOKUP(2,1/(数据收集总表!M3:M31<>""),数据收集总表!M3:M31) | D4: =IF(C4>=0.5,100,IF(C4<=-0.5,0,(C4+0.5)*100)) | E4: =D4*VALUE(SUBSTITUTE(B4,"%",""))/100 | F4: ≥+0.5%=100, ≤-0.5%=0, 线性插值
A5: 布林带状态 | B5: 20% | C5: =LOOKUP(2,1/(数据收集总表!N3:N31<>""),数据收集总表!N3:N31) | D5: =C5 | E5: =D5*VALUE(SUBSTITUTE(B5,"%",""))/100 | F5: 触下轨扩口=100, 触上轨扩口=0, 其他=50
A6: 趋势层总分 T | D6: =SUM(E2:E5)
A7: K_trend | D7: =1+(D6/100-0.5)*0.4

Sheet 流动性地缘乘数表
A1: K_liquidity 计算
A3: 当前VIX | B3: =LOOKUP(2,1/(数据收集总表!O3:O31<>""),数据收集总表!O3:O31)
A4: 当前信用利差(%) | B4: =LOOKUP(2,1/(数据收集总表!P3:P31<>""),数据收集总表!P3:P31)
A5: K_liquidity | B5: =IF(B3>=35,0.5,IF(B3>=25,IF(B4>=3,0.7,0.8),IF(B3>=15,IF(B4>=3,0.9,1),IF(B4>=3,1,1.2))))
A8: K_geo 计算
A10: 当前GPR | B10: =LOOKUP(2,1/(数据收集总表!Q3:Q31<>""),数据收集总表!Q3:Q31) | C10: 120 | D10: 100
A11: 当前布油($) | B11: =LOOKUP(2,1/(数据收集总表!R3:R31<>""),数据收集总表!R3:R31) | C11: 120 | D11: 100
A12: 当前CPI(%) | B12: =LOOKUP(2,1/(数据收集总表!S3:S31<>""),数据收集总表!S3:S31)
A13: Fed编码 | B13: =宏观信号计算表!D8
A15: K_geo | B15: =IF(B10>C10,IF(B11>C11,IF(B12>4,1.2,IF(B13=-1,0.95,1.1)),IF(B11>D11,IF(B13=-1,0.95,1.1),1.1)),IF(B10>D10,IF(B11>C11,IF(B12>4,1,IF(B13=-1,0.98,1.05)),IF(B11>D11,IF(B13=-1,0.98,1.05),1.05)),1))
A18: K_geo 查表矩阵 (参考)
A19: GPR连续3月 | B19: 布油>$120+CPI>4% | C19: 布油$100-120+Fed=-1 | D19: 布油$100-120+Fed=0/+1 | E19: 布油<$100
A20: >120 | B20: 1.20 | C20: 0.95 | D20: 1.10 | E20: 1.10
A21: 100-120 | B21: — | C21: 0.98 | D21: 1.05 | E21: 1.05
A22: ≤100 | B22: 1.00 | C22: 1.00 | D22: 1.00 | E22: 1.00

Sheet 综合信号计算表
A1: 最终信号生成
A3: 计算步骤 | B3: 因子 | C3: 数值 | D3: 公式说明
A4: 第1步 | B4: S_macro | C4: =宏观信号计算表!E11 | D4: 宏观驱动信号
A5: 第2步 | B5: K_verif | C5: =验证层计算表!D6 | D5: 市场验证乘数
A6: 第3步 | B6: K_trend | C6: =趋势层计算表!D7 | D6: 趋势动量乘数
A7: 第4步 | B7: K_liquidity | C7: =流动性地缘乘数表!B5 | D7: 流动性乘数
A8: 第5步 | B8: K_geo | C8: =流动性地缘乘数表!B15 | D8: 地缘乘数
A9: 第6步 | B9: 原始信号 | C9: =C4*C5*C6*C7*C8 | D9: 五项相乘
A10: 第7步 | B10: 强制规则检查 | C10: =IF(强制规则检查表!E2<>"","触发",IF(强制规则检查表!E3<>"","触发",IF(强制规则检查表!E4<>"","触发",IF(强制规则检查表!E5<>"","触发","未触发")))) | D10: 见工作表7
A11: 第8步 | B11: 最终信号 | C11: =IF(强制规则检查表!E2<>"",强制规则检查表!D2,IF(强制规则检查表!E3<>"",强制规则检查表!D3,IF(强制规则检查表!E4<>"",强制规则检查表!D4,IF(强制规则检查表!E5<>"",强制规则检查表!D5,C9)))) | D11: 强制规则覆盖
A14: 信号等级 | B14: 仓位建议 | C14: 信号范围
A15: 🔥 强力看多 | B15: 16%-20% | C15: ≥+0.60
A16: ✅ 看多 | B16: 9%-16% | C16: +0.35~+0.60
A17: 🟡 偏多 | B17: 6%-9% | C17: +0.15~+0.35
A18: ⚪ 中性 | B18: 3%-6% | C18: -0.15~+0.15
A19: 🟠 偏空 | B19: 1%-30% | C19: -0.35~-0.15
A20: 🔴 看空 | B20: 0%-1% | C20: ≤-0.35
A22: 当前信号等级: | B22: =IF(C11>=0.6,"🔥 强力看多",IF(C11>=0.35,"✅ 看多",IF(C11>=0.15,"🟡 偏多",IF(C11>=-0.15,"⚪ 中性",IF(C11>=-0.35,"🟠 偏空","🔴 看空")))))
A23: 建议仓位: | B23: =IF(C11>=0.6,B15,IF(C11>=0.35,B16,IF(C11>=0.15,B17,IF(C11>=-0.15,B18,IF(C11>=-0.35,B19,B20)))))

Sheet 强制规则检查表
A1: 规则ID | B1: 触发条件 | C1: 判断公式 | D1: 强制动作 | E1: 是否触发
A2: OR-03 | B2: VIX≥35 且 黄金-1%美元+0.5% | C2: =AND(流动性地缘乘数表!B3>=35,LOOKUP(2,1/(数据收集总表!U3:U31<>""),数据收集总表!U3:U31)<=-0.01,LOOKUP(2,1/(数据收集总表!V3:V31<>""),数据收集总表!V3:V31)>=0.005) | D2: -0.5 | E2: =IF(C2=TRUE,D2,"")
A3: OR-01 | B3: 趋势层总分<20 | C3: =趋势层计算表!D6<20 | D3: -0.2 | E3: =IF(C3=TRUE,D3,"")
A4: OR-02 | B4: 趋势层总分>80 | C4: =趋势层计算表!D6>80 | D4: 0.3 | E4: =IF(C4=TRUE,D4,"")
A5: 结构牛底线 | B5: 连续两季购金>300吨 | C5: =FALSE | D5: 0.15 | E5: =IF(C5=TRUE,D5,"")

Sheet 操作日志
A1: 日期 | B1: 操作类型 | C1: 数据项 | D1: 原值 | E1: 新值 | F1: 信号变化前 | G1: 信号变化后 | H1: 备注
